tests/large.in
4
o
2 B 100 RNLF 1059 16
3 S 101 QLJR 2068 26
2 C 100
3 C 101
0 S 102 NSUU 2337 24
0 C 102
0 B 103 RNLF 1130 22
3 B 104 RNLF 1201 28
2 S 105 QLJR 2068 21
2 S 106 RNLF 1089 28
2 S 107 ZXTI 1682 28
0 C 102
2 B 108 RNLF 1137 26
1 S 109 RNLF 1115 21
1 B 110 ZXTI 1675 24
3 C 104
2 C 108
2 C 107
3 S 111 ZXTI 1775 16
3 S 112 QLJR 2023 17
1 S 113 ZXTI 1720 30
1 B 114 QLJR 1984 24
2 B 115 NSUU 2310 15
1 S 116 NSUU 2331 22
3 S 117 ZXTI 1663 21
1 S 118 ZXTI 1724 29
0 B 119 ZXTI 1673 22
2 S 120 QLJR 2066 14
2 S 121 ZXTI 1694 22
0 B 122 QLJR 2058 27
2 S 123 NSUU 2162 10
2 S 124 NSUU 2184 22
3 S 125 RNLF 1101 25
2 B 126 ZXTI 1831 19
2 C 121
0 S 127 QLJR 2032 19
1 C 109
2 C 107
2 S 128 QLJR 2122 18
3 C 111
3 S 129 ZXTI 1680 12
3 B 130 RNLF 1073 30
0 B 131 RNLF 1115 25
3 B 132 RNLF 1084 12
3 S 133 RNLF 1054 25
1 S 134 QLJR 2128 13
2 C 126
1 C 114
1 S 135 QLJR 2034 12
3 C 133
1 C 135
3 B 136 RNLF 1105 17
3 B 137 NSUU 2285 12
2 S 138 RNLF 1174 23
2 S 139 RNLF 1118 17
0 B 140 NSUU 2252 23
0 C 119
3 S 141 NSUU 2243 15
3 S 142 QLJR 2064 14
0 S 143 QLJR 2138 12
3 B 144 NSUU 2160 12
1 S 145 RNLF 1205 21
0 B 146 QLJR 2031 16
2 C 120
3 C 117
1 C 109
2 B 147 QLJR 2174 17
2 B 148 QLJR 2123 30
1 C 116
1 B 149 QLJR 1980 14
3 C 117
3 C 142
1 B 150 QLJR 2124 30
1 C 150
0 B 151 NSUU 2239 11
2 C 121
2 C 100
3 C 141
3 C 142
2 S 152 NSUU 2231 23
0 B 153 ZXTI 1753 18
2 B 154 ZXTI 1662 20
3 B 155 QLJR 2158 16
1 S 156 RNLF 1075 22
3 B 157 NSUU 2203 10
1 S 158 RNLF 1070 17
1 S 159 ZXTI 1846 26
1 S 160 QLJR 2009 29
3 C 141
3 S 161 NSUU 2294 12
3 S 162 ZXTI 1661 16
1 S 163 RNLF 1031 16
1 B 164 ZXTI 1697 24
1 C 116
3 C 141
3 C 133
3 S 165 ZXTI 1779 17
1 C 118
1 B 166 RNLF 1129 29
1 C 156
x
